Workbook

Sheet Data
A1: Anthropic, PBC - data from the Form S-1 (USD millions unless stated)
A2: Blue = typed from the S-1 (page in column I). Black = formula. LTM Jun-26 = FY2025 + 6M2026 - 6M2025.
A4: Income statement (GAAP) | B4: FY2023 | C4: FY2024 | D4: FY2025 | E4: 6M2025 | F4: 6M2026 | G4: LTM Jun-26 | H4: Unit | I4: Source
A5: Revenue - consumption-based | B5: 39 | C5: 288 | D5: 3796 | E5: 983 | F5: 13064 | G5: =D5+F5-E5 -> 15877 | H5: USD m | I5: S-1 p.F-26 (PDF p.276)
A6: Revenue - subscription-based | B6: 2 | C6: 98 | D6: 789 | E6: 180 | F6: 3222 | G6: =D6+F6-E6 -> 3831 | H6: USD m | I6: S-1 p.F-26 (PDF p.276)
A7: Revenue | B7: =B5+B6 -> 41 | C7: =C5+C6 -> 386 | D7: =D5+D6 -> 4585 | E7: =E5+E6 -> 1163 | F7: =F5+F6 -> 16286 | G7: =G5+G6 -> 19708 | H7: USD m | I7: Formula
A8: Revenue - United States | B8: 34 | C8: 263 | D8: 3362 | E8: 820 | F8: 11763 | G8: =D8+F8-E8 -> 14305 | H8: USD m | I8: S-1 p.F-26 (PDF p.276)
A9: Revenue - International | B9: 7 | C9: 123 | D9: 1223 | E9: 343 | F9: 4523 | G9: =D9+F9-E9 -> 5403 | H9: USD m | I9: S-1 p.F-26 (PDF p.276)
A10: Compute and infrastructure | B10: 433 | C10: 2522 | D10: 7326 | E10: 2334 | F10: 8945 | G10: =D10+F10-E10 -> 13937 | H10: USD m | I10: S-1 p.F-7 (PDF p.263)
A11: Personnel (incl. stock-based compensation) | B11: 95 | C11: 454 | D11: 1839 | E11: 538 | F11: 3152 | G11: =D11+F11-E11 -> 4453 | H11: USD m | I11: S-1 p.F-7 (PDF p.263)
A12: Bartz settlement | B12: 0 | C12: 0 | D12: 1500 | E12: 0 | F12: 0 | G12: =D12+F12-E12 -> 1500 | H12: USD m | I12: S-1 p.F-7 (PDF p.263)
A13: Sales, marketing, and partnerships | B13: 2 | C13: 43 | D13: 568 | E13: 120 | F13: 3168 | G13: =D13+F13-E13 -> 3616 | H13: USD m | I13: S-1 p.F-7 (PDF p.263)
A14: Other operating and administrative | B14: 62 | C14: 347 | D14: 1412 | E14: 306 | F14: 1714 | G14: =D14+F14-E14 -> 2820 | H14: USD m | I14: S-1 p.F-7 (PDF p.263)
A15: Total operating expenses | B15: =B10+B11+B12+B13+B14 -> 592 | C15: =C10+C11+C12+C13+C14 -> 3366 | D15: =D10+D11+D12+D13+D14 -> 12645 | E15: =E10+E11+E12+E13+E14 -> 3298 | F15: =F10+F11+F12+F13+F14 -> 16979 | G15: =G10+G11+G12+G13+G14 -> 26326 | H15: USD m | I15: Formula
A16: Operating income (loss) | B16: =B7-B15 -> -551 | C16: =C7-C15 -> -2980 | D16: =D7-D15 -> -8060 | E16: =E7-E15 -> -2135 | F16: =F7-F15 -> -693 | G16: =G7-G15 -> -6618 | H16: USD m | I16: Formula
A17: Interest income | B17: 69 | C17: 106 | D17: 431 | E17: 115 | F17: 1111 | G17: =D17+F17-E17 -> 1427 | H17: USD m | I17: S-1 p.F-7 (PDF p.263)
A18: Change in fair value of convertible notes, derivatives and SAFEs | B18: -1045 | C18: -5434 | D18: -34308 | E18: -10942 | F18: -72388 | G18: =D18+F18-E18 -> -95754 | H18: USD m | I18: S-1 p.F-7 (PDF p.263)
A19: Other income (expense), net | B19: -2 | C19: 0 | D19: -8 | E19: 0 | F19: -8757 | G19: =D19+F19-E19 -> -8765 | H19: USD m | I19: S-1 p.F-7 (PDF p.263)
A20: Loss before income taxes | B20: =B16+B17+B18+B19 -> -1529 | C20: =C16+C17+C18+C19 -> -8308 | D20: =D16+D17+D18+D19 -> -41945 | E20: =E16+E17+E18+E19 -> -12962 | F20: =F16+F17+F18+F19 -> -80727 | G20: =G16+G17+G18+G19 -> -109710 | H20: USD m | I20: Formula
A21: Provision for income taxes | B21: 2 | C21: 1 | D21: 20 | E21: 7 | F21: 21 | G21: =D21+F21-E21 -> 34 | H21: USD m | I21: S-1 p.F-7 (PDF p.263)
A22: Net income (loss) | B22: =B20-B21 -> -1531 | C22: =C20-C21 -> -8309 | D22: =D20-D21 -> -41965 | E22: =E20-E21 -> -12969 | F22: =F20-F21 -> -80748 | G22: =G20-G21 -> -109744 | H22: USD m | I22: Formula
A23: Weighted-average shares, basic and diluted | B23: 1076880510 | C23: 1528994540 | D23: 1821084860 | E23: 1788730900 | F23: 2024972990 | H23: shares | I23: S-1 p.22 (PDF p.25)
A24: Net loss per share, basic and diluted | B24: =B22*1000000/B23 -> -1.4216991 | C24: =C22*1000000/C23 -> -5.4342902 | D24: =D22*1000000/D23 -> -23.043956 | E24: =E22*1000000/E23 -> -7.2503919 | F24: =F22*1000000/F23 -> -39.876087 | H24: USD/share | I24: Formula
A26: Operating expenses by function (Note 8) | B26: FY2023 | C26: FY2024 | D26: FY2025 | E26: 6M2025 | F26: 6M2026 | G26: LTM Jun-26 | H26: Unit | I26: Source
A27: Cost of revenue (customer-serving compute) | B27: 26 | C27: 752 | D27: 2773 | E27: 1019 | F27: 2380 | G27: =D27+F27-E27 -> 4134 | H27: USD m | I27: S-1 p.F-39 (PDF p.286)
A28: Research and development | B28: 422 | C28: 2275 | D28: 6338 | E28: 1850 | F28: 9741 | G28: =D28+F28-E28 -> 14229 | H28: USD m | I28: S-1 p.F-39 (PDF p.286)
A29: Sales and marketing | B29: 76 | C29: 163 | D29: 911 | E29: 239 | F29: 3808 | G29: =D29+F29-E29 -> 4480 | H29: USD m | I29: S-1 p.F-39 (PDF p.286)
A30: Bartz settlement | B30: 0 | C30: 0 | D30: 1500 | E30: 0 | F30: 0 | G30: =D30+F30-E30 -> 1500 | H30: USD m | I30: S-1 p.F-39 (PDF p.286)
A31: General and administrative | B31: 68 | C31: 176 | D31: 1123 | E31: 190 | F31: 1050 | G31: =D31+F31-E31 -> 1983 | H31: USD m | I31: S-1 p.F-39 (PDF p.286)
A32: Total operating expenses | B32: =B27+B28+B29+B30+B31 -> 592 | C32: =C27+C28+C29+C30+C31 -> 3366 | D32: =D27+D28+D29+D30+D31 -> 12645 | E32: =E27+E28+E29+E30+E31 -> 3298 | F32: =F27+F28+F29+F30+F31 -> 16979 | G32: =G27+G28+G29+G30+G31 -> 26326 | H32: USD m | I32: Formula
A33: Gross profit (revenue - cost of revenue) | B33: =B7-B27 -> 15 | C33: =C7-C27 -> -366 | D33: =D7-D27 -> 1812 | E33: =E7-E27 -> 144 | F33: =F7-F27 -> 13906 | G33: =G7-G27 -> 15574 | H33: USD m | I33: Formula
A35: Non-GAAP reconciliation (company definitions) | B35: FY2023 | C35: FY2024 | D35: FY2025 | E35: 6M2025 | F35: 6M2026 | G35: LTM Jun-26 | H35: Unit | I35: Source
A36: Stock-based compensation | B36: 29 | C36: 192 | D36: 1165 | E36: 286 | F36: 2185 | G36: =D36+F36-E36 -> 3064 | H36: USD m | I36: S-1 p.156 (PDF p.125)
A37: Non-cash charitable contributions (donation matching) | B37: 0 | C37: 0 | D37: 541 | E37: 0 | F37: 126 | G37: =D37+F37-E37 -> 667 | H37: USD m | I37: S-1 p.156 (PDF p.125)
A38: Change in FV of mark-to-market financial instruments | B38: 0 | C38: 0 | D38: 3 | E38: 0 | F38: 8720 | G38: =D38+F38-E38 -> 8723 | H38: USD m | I38: S-1 p.156 (PDF p.125)
A39: Depreciation and amortization (cash flow statement) | B39: 3 | C39: 21 | D39: 40 | E39: 14 | F39: 97 | G39: =D39+F39-E39 -> 123 | H39: USD m | I39: S-1 p.F-12 (PDF p.266)
A40: Adjusted Operating Income = operating loss + SBC + donations + Bartz | B40: =B16+B36+B37+B12 -> -522 | C40: =C16+C36+C37+C12 -> -2788 | D40: =D16+D36+D37+D12 -> -4854 | E40: =E16+E36+E37+E12 -> -1849 | F40: =F16+F36+F37+F12 -> 1618 | G40: =G16+G36+G37+G12 -> -1387 | H40: USD m | I40: Formula; S-1 p.155
A41: Adjusted Net Income = net loss + SBC + donations + Bartz + FV changes | B41: =B22+B36+B37+B12-B18+B38 -> -457 | C41: =C22+C36+C37+C12-C18+C38 -> -2683 | D41: =D22+D36+D37+D12-D18+D38 -> -4448 | E41: =E22+E36+E37+E12-E18+E38 -> -1741 | F41: =F22+F36+F37+F12-F18+F38 -> 2671 | G41: =G22+G36+G37+G12-G18+G38 -> -36 | H41: USD m | I41: Formula; S-1 p.156
A42: Adjusted EBITDA = Adjusted Operating Income + D&A (not reported by company) | B42: =B40+B39 -> -519 | C42: =C40+C39 -> -2767 | D42: =D40+D39 -> -4814 | E42: =E40+E39 -> -1835 | F42: =F40+F39 -> 1715 | G42: =G40+G39 -> -1264 | H42: USD m | I42: Own calculation
A44: Cash flow statement | B44: FY2023 | C44: FY2024 | D44: FY2025 | E44: 6M2025 | F44: 6M2026 | G44: LTM Jun-26 | H44: Unit | I44: Source
...

Sheet Ratios
A1: Ratios by period (formulas reference the Data sheet)
A2: N/A = not computable from the S-1 (no 6M2024 or Jun-2025 figures).
A4: Growth | B4: FY2023 | C4: FY2024 | D4: FY2025 | E4: 6M2025 | F4: 6M2026 | G4: LTM Jun-26 | H4: Formula
A5: Revenue growth y/y | B5: N/A | C5: =Data!C7/Data!$B$7-1 -> 8.4146341 | D5: =Data!D7/Data!$C$7-1 -> 10.878238 | E5: N/A | F5: =Data!F7/Data!$E$7-1 -> 13.003439 | G5: N/A | H5: Revenue / prior-period revenue - 1 (6M2026 vs 6M2025)
A6: Consumption revenue growth y/y | B6: N/A | C6: =Data!C5/Data!$B$5-1 -> 6.3846154 | D6: =Data!D5/Data!$C$5-1 -> 12.180556 | E6: N/A | F6: =Data!F5/Data!$E$5-1 -> 12.289929 | G6: N/A | H6: Consumption revenue / prior period - 1
A7: Subscription revenue growth y/y | B7: N/A | C7: =Data!C6/Data!$B$6-1 -> 48 | D7: =Data!D6/Data!$C$6-1 -> 7.0510204 | E7: N/A | F7: =Data!F6/Data!$E$6-1 -> 16.9 | G7: N/A | H7: Subscription revenue / prior period - 1
A8: Consumption share of revenue | B8: =Data!B5/Data!B7 -> 0.95121951 | C8: =Data!C5/Data!C7 -> 0.74611399 | D8: =Data!D5/Data!D7 -> 0.82791712 | E8: =Data!E5/Data!E7 -> 0.84522786 | F8: =Data!F5/Data!F7 -> 0.80216137 | G8: =Data!G5/Data!G7 -> 0.80561193 | H8: Consumption revenue / revenue
A10: Profitability | B10: FY2023 | C10: FY2024 | D10: FY2025 | E10: 6M2025 | F10: 6M2026 | G10: LTM Jun-26 | H10: Formula
A11: Gross margin (Note 8) | B11: =Data!B33/Data!B7 -> 0.36585366 | C11: =Data!C33/Data!C7 -> -0.94818653 | D11: =Data!D33/Data!D7 -> 0.39520174 | E11: =Data!E33/Data!E7 -> 0.12381771 | F11: =Data!F33/Data!F7 -> 0.85386221 | G11: =Data!G33/Data!G7 -> 0.79023747 | H11: (Revenue - cost of revenue) / revenue; excludes training compute
A12: Operating margin (GAAP) | B12: =Data!B16/Data!B7 -> -13.439024 | C12: =Data!C16/Data!C7 -> -7.7202073 | D12: =Data!D16/Data!D7 -> -1.7579062 | E12: =Data!E16/Data!E7 -> -1.8357696 | F12: =Data!F16/Data!F7 -> -0.042551885 | G12: =Data!G16/Data!G7 -> -0.33580272 | H12: Operating income / revenue
A13: Net margin (GAAP) | B13: =Data!B22/Data!B7 -> -37.341463 | C13: =Data!C22/Data!C7 -> -21.525907 | D13: =Data!D22/Data!D7 -> -9.1526718 | E13: =Data!E22/Data!E7 -> -11.151333 | F13: =Data!F22/Data!F7 -> -4.9581235 | G13: =Data!G22/Data!G7 -> -5.5685001 | H13: Net income / revenue
A14: Adjusted operating margin (non-GAAP) | B14: =Data!B40/Data!B7 -> -12.731707 | C14: =Data!C40/Data!C7 -> -7.2227979 | D14: =Data!D40/Data!D7 -> -1.0586696 | E14: =Data!E40/Data!E7 -> -1.5898538 | F14: =Data!F40/Data!F7 -> 0.099349134 | G14: =Data!G40/Data!G7 -> -0.070377512 | H14: Adjusted Operating Income / revenue
A15: Adjusted EBITDA margin (own calculation) | B15: =Data!B42/Data!B7 -> -12.658537 | C15: =Data!C42/Data!C7 -> -7.1683938 | D15: =Data!D42/Data!D7 -> -1.0499455 | E15: =Data!E42/Data!E7 -> -1.577816 | F15: =Data!F42/Data!F7 -> 0.10530517 | G15: =Data!G42/Data!G7 -> -0.064136391 | H15: (Adjusted Operating Income + D&A) / revenue
A17: Cash flow | B17: FY2023 | C17: FY2024 | D17: FY2025 | E17: 6M2025 | F17: 6M2026 | G17: LTM Jun-26 | H17: Formula
A18: Free cash flow (USD m) | B18: =Data!B57+Data!B58 -> -1629 | C18: =Data!C57+Data!C58 -> -5707 | D18: =Data!D57+Data!D58 -> -2768 | E18: =Data!E57+Data!E58 -> -1531 | F18: =Data!F57+Data!F58 -> 3447 | G18: =Data!G57+Data!G58 -> 2210 | H18: Operating cash flow - capex
A19: FCF margin | B19: =B18/Data!B7 -> -39.731707 | C19: =C18/Data!C7 -> -14.784974 | D19: =D18/Data!D7 -> -0.60370774 | E19: =E18/Data!E7 -> -1.316423 | F19: =F18/Data!F7 -> 0.21165418 | G19: =G18/Data!G7 -> 0.1121372 | H19: FCF / revenue
A20: Cash burn (USD m; 0 = cash generative) | B20: =MAX(0,-B18) -> 1629 | C20: =MAX(0,-C18) -> 5707 | D20: =MAX(0,-D18) -> 2768 | E20: =MAX(0,-E18) -> 1531 | F20: =MAX(0,-F18) -> 0 | G20: =MAX(0,-G18) -> 0 | H20: max(0, -FCF)
A21: Cash and short-term investments at period end (USD m) | B21: N/A | C21: =Data!$B$103 -> 3141 | D21: =Data!$C$103 -> 20277 | E21: N/A | F21: =Data!$D$103 -> 131651 | G21: =Data!$D$103 -> 131651 | H21: Balance sheet at period end
A22: Runway in years (N/A = no burn or no balance sheet) | B22: =IF(OR(ISTEXT(B21),B20=0),"N/A",B21/(B20*1)) -> N/A | C22: =IF(OR(ISTEXT(C21),C20=0),"N/A",C21/(C20*1)) -> 0.55037673 | D22: =IF(OR(ISTEXT(D21),D20=0),"N/A",D21/(D20*1)) -> 7.3255058 | E22: =IF(OR(ISTEXT(E21),E20=0),"N/A",E21/(E20*2)) -> N/A | F22: =IF(OR(ISTEXT(F21),F20=0),"N/A",F21/(F20*1)) -> N/A | G22: =IF(OR(ISTEXT(G21),G20=0),"N/A",G21/(G20*1)) -> N/A | H22: Cash and STI / annualised burn
A24: Cost structure (% of revenue) | B24: FY2023 | C24: FY2024 | D24: FY2025 | E24: 6M2025 | F24: 6M2026 | G24: LTM Jun-26 | H24: Formula
A25: Compute and infrastructure / revenue | B25: =Data!B10/Data!B7 -> 10.560976 | C25: =Data!C10/Data!C7 -> 6.5336788 | D25: =Data!D10/Data!D7 -> 1.597819 | E25: =Data!E10/Data!E7 -> 2.0068788 | F25: =Data!F10/Data!F7 -> 0.54924475 | G25: =Data!G10/Data!G7 -> 0.70717475 | H25: All compute (serving, training, research)
A26: R&D / revenue | B26: =Data!B28/Data!B7 -> 10.292683 | C26: =Data!C28/Data!C7 -> 5.8937824 | D26: =Data!D28/Data!D7 -> 1.3823337 | E26: =Data!E28/Data!E7 -> 1.5907137 | F26: =Data!F28/Data!F7 -> 0.59812109 | G26: =Data!G28/Data!G7 -> 0.72199107 | H26: R&D (Note 8) / revenue
A27: Stock-based compensation / revenue | B27: =Data!B36/Data!B7 -> 0.70731707 | C27: =Data!C36/Data!C7 -> 0.49740933 | D27: =Data!D36/Data!D7 -> 0.25408942 | E27: =Data!E36/Data!E7 -> 0.24591574 | F27: =Data!F36/Data!F7 -> 0.13416431 | G27: =Data!G36/Data!G7 -> 0.15546986 | H27: SBC / revenue
A28: Sales, marketing and partnerships / revenue | B28: =Data!B13/Data!B7 -> 0.048780488 | C28: =Data!C13/Data!C7 -> 0.11139896 | D28: =Data!D13/Data!D7 -> 0.12388222 | E28: =Data!E13/Data!E7 -> 0.10318143 | F28: =Data!F13/Data!F7 -> 0.1945229 | G28: =Data!G13/Data!G7 -> 0.18347879 | H28: SM&P / revenue
A30: Capital | B30: FY2023 | C30: FY2024 | D30: FY2025 | E30: 6M2025 | F30: 6M2026 | G30: LTM Jun-26 | H30: Formula
A31: Capex / revenue | B31: =-Data!B58/Data!B7 -> 0.048780488 | C31: =-Data!C58/Data!C7 -> 0.038860104 | D31: =-Data!D58/Data!D7 -> 0.028571429 | E31: =-Data!E58/Data!E7 -> 0.015477214 | F31: =-Data!F58/Data!F7 -> 0.029595972 | G31: =-Data!G58/Data!G7 -> 0.030190785 | H31: Capex / revenue
A32: (Capex + finance-lease equipment) / revenue | B32: =(-Data!B58+Data!B75)/Data!B7 -> 0.048780488 | C32: =(-Data!C58+Data!C75)/Data!C7 -> 0.038860104 | D32: =(-Data!D58+Data!D75)/Data!D7 -> 0.028571429 | E32: =(-Data!E58+Data!E75)/Data!E7 -> 0.015477214 | F32: =(-Data!F58+Data!F75)/Data!F7 -> 0.056920054 | G32: =(-Data!G58+Data!G75)/Data!G7 -> 0.052770449 | H32: (Capex + finance-lease additions) / revenue
A33: Purchase commitments / revenue (x) | B33: N/A | C33: N/A | D33: =Data!$B$142/Data!$D$7 -> 11.899455 | E33: N/A | F33: N/A | G33: =Data!$B$143/Data!$G$7 -> 13.476761 | H33: Dec-25 commitments / FY2025 revenue; Jun-26 / LTM revenue
A34: Signed leases not yet commenced / revenue (x) | B34: N/A | C34: N/A | D34: =Data!$B$144/Data!$D$7 -> 10.948746 | E34: N/A | F34: N/A | G34: =Data!$B$145/Data!$G$7 -> 16.308098 | H34: Undiscounted signed leases / revenue
A36: Concentration | B36: FY2023 | C36: FY2024 | D36: FY2025 | E36: 6M2025 | F36: 6M2026 | G36: Latest | H36: Formula
A37: Largest single customer | B37: =IF(MAX(Data!B128,Data!B129,Data!B130,Data!B131)=0,"<10%",MAX(Data!B128,Data!B129,Data!B130,Data!B131)) -> 0.43 | C37: =IF(MAX(Data!C128,Data!C129,Data!C130,Data!C131)=0,"<10%",MAX(Data!C128,Data!C129,Data!C130,Data!C131)) -> <10% | D37: =IF(MAX(Data!D128,Data!D129,Data!D130,Data!D131)=0,"<10%",MAX(Data!D128,Data!D129,Data!D130,Data!D131)) -> 0.12 | E37: =IF(MAX(Data!E128,Data!E129,Data!E130,Data!E131)=0,"<10%",MAX(Data!E128,Data!E129,Data!E130,Data!E131)) -> 0.18 | F37: =IF(MAX(Data!F128,Data!F129,Data!F130,Data!F131)=0,"<10%",MAX(Data!F128,Data!F129,Data!F130,Data!F131)) -> 0.11 | G37: N/A | H37: Largest of Customers A-D; <10% if none reaches 10%
A38: Top five customers (Latest = 9M-2026) | G38: =Data!$G$133 -> 0.25 | H38: S-1 Risk Factors
A39: Sold through cloud marketplaces | B39: =Data!B132 -> 0.11 | C39: =Data!C132 -> 0.32 | D39: =Data!D132 -> 0.47 | E39: =Data!E132 -> 0.44 | F39: =Data!F132 -> 0.48 | G39: N/A | H39: S-1 Note 1
A40: Revenue from customers with >=$100k TTM revenue | B40: =Data!B122 -> 0.9 | C40: =Data!C122 -> 0.57 | D40: =Data!D122 -> 0.76 | E40: N/A | F40: N/A | G40: N/A | H40: S-1 MD&A
A41: United States share of revenue | B41: =Data!B8/Data!B7 -> 0.82926829 | C41: =Data!C8/Data!C7 -> 0.68134715 | D41: =Data!D8/Data!D7 -> 0.73326063 | E41: =Data!E8/Data!E7 -> 0.70507309 | F41: =Data!F8/Data!F7 -> 0.7222768 | G41: =Data!G8/Data!G7 -> 0.72584737 | H41: US revenue / revenue
A43: Quarterly | B43: Q1-2025 | C43: Q2-2025 | D43: Q3-2025 | E43: Q4-2025 | F43: Q1-2026 | G43: Q2-2026 | H43: Formula
A44: Revenue growth q/q | B44: N/A | C44: =Data!C107/Data!B107-1 -> 1.0930851 | D44: =Data!D107/Data!C107-1 -> 0.75603558 | E44: =Data!E107/Data!D107-1 -> 0.47612156 | F44: =Data!F107/Data!E107-1 -> 1.3191176 | G44: =Data!G107/Data!F107-1 -> 1.4424012 | H44: Revenue / prior-quarter revenue - 1
A45: Compute and infrastructure / revenue | B45: =Data!B108/Data!B107 -> 2.5106383 | C45: =Data!C108/Data!C107 -> 1.7662008 | D45: =Data!D108/Data!D107 -> 1.4811867 | E45: =Data!E108/Data!E107 -> 1.4436275 | F45: =Data!F108/Data!F107 -> 0.7159163 | G45: =Data!G108/Data!G107 -> 0.48100389 | H45: Compute and infrastructure / revenue
A46: Operating margin (GAAP) | B46: =Data!B114/Data!B107 -> -2.4867021 | C46: =Data!C114/Data!C107 -> -1.5247776 | D46: =Data!D114/Data!D107 -> -2.2351664 | E46: =Data!E114/Data!E107 -> -1.3901961 | F46: =Data!F114/Data!F107 -> -0.3523568 | G46: =Data!G114/Data!G107 -> 0.084292514 | H46: Operating income / revenue
A47: Adjusted operating margin (non-GAAP) | B47: =Data!B117/Data!B107 -> -2.2074468 | C47: =Data!C117/Data!C107 -> -1.2947903 | D47: =Data!D117/Data!D107 -> -0.92908828 | E47: =Data!E117/Data!E107 -> -0.84362745 | F47: =Data!F117/Data!F107 -> -0.1304164 | G47: =Data!G117/Data!G107 -> 0.19342276 | H47: Adjusted Operating Income / revenue

Sheet Sources
A1: Sources and gaps
A2: S-1 = Anthropic, PBC Form S-1 filed 26 Oct 2026 (Anthropic/Anthropic, PBC - S-1 (Q2).pdf). Page = printed S-1 page; PDF = page of the PDF file. Each number on the Data sheet carries its own citation.
A4: Item | B4: S-1 section | C4: Pages
A5: Income statement | B5: Consolidated Statements of Operations | C5: S-1 p.F-7 (PDF 263)
A6: Balance sheet | B6: Consolidated Balance Sheets | C6: S-1 p.F-5 to F-6 (PDF 261-262)
A7: Cash flow statement | B7: Consolidated Statements of Cash Flows | C7: S-1 p.F-12 to F-13 (PDF 266-267)
A8: Expenses by function | B8: Note 8 Supplemental Financial Information | C8: S-1 p.F-39 (PDF 286)
A9: Revenue split | B9: Note 2 Revenue | C9: S-1 p.F-26 (PDF 276)
A10: Customer concentration | B10: Note 1 Concentrations of Risk | C10: S-1 p.F-15 to F-16 (PDF 268-269)
A11: Quarterly results | B11: MD&A Quarterly Results of Operations | C11: S-1 p.157-160 (PDF 125-128)
A12: Non-GAAP reconciliation | B12: MD&A Non-GAAP Financial Measures | C12: S-1 p.155-156 (PDF 124-125)
A13: Operating metrics | B13: MD&A Our Financial Model / Key Factors | C13: S-1 p.133-143 (PDF 108-115)
A14: Compute agreements | B14: MD&A Contractual Obligations | C14: S-1 p.169-171 (PDF 134-136)
A15: Purchase commitments | B15: Note 13 Commitments and Contingencies | C15: S-1 p.F-58 (PDF 300-301)
... A41: Principal stockholders percentages | B41: Principal and Selling Stockholders (S-1 p.288-289, PDF p.224) | C41: N/A - not found (most percentages blank)

Sheet Checks
A1: Checks - every line must return TRUE
A2: Model formulas are compared with totals reported in the S-1.
A4: Check | B4: Result | C4: Detail
A5: rev: formula equals S-1 reported total, all five periods | B5: =AND(ABS(Data!B7-(41))<0.5,ABS(Data!C7-(386))<0.5,ABS(Data!D7-(4585))<0.5,ABS(Data!E7-(1163))<0.5,ABS(Data!F7-(16286))<0.5) -> TRUE | C5: S-1: 41, 386, 4585, 1163, 16286
A6: opex: formula equals S-1 reported total, all five periods | B6: =AND(ABS(Data!B15-(592))<0.5,ABS(Data!C15-(3366))<0.5,ABS(Data!D15-(12645))<0.5,ABS(Data!E15-(3298))<0.5,ABS(Data!F15-(16979))<0.5) -> TRUE | C6: S-1: 592, 3366, 12645, 3298, 16979
A7: ebit: formula equals S-1 reported total, all five periods | B7: =AND(ABS(Data!B16-(-551))<0.5,ABS(Data!C16-(-2980))<0.5,ABS(Data!D16-(-8060))<0.5,ABS(Data!E16-(-2135))<0.5,ABS(Data!F16-(-693))<0.5) -> TRUE | C7: S-1: -551, -2980, -8060, -2135, -693
A8: ni: formula equals S-1 reported total, all five periods | B8: =AND(ABS(Data!B22-(-1531))<0.5,ABS(Data!C22-(-8309))<0.5,ABS(Data!D22-(-41965))<0.5,ABS(Data!E22-(-12969))<0.5,ABS(Data!F22-(-80748))<0.5) -> TRUE | C8: S-1: -1531, -8309, -41965, -12969, -80748
A9: cfo: formula equals S-1 reported total, all five periods | B9: =AND(ABS(Data!B57-(-1627))<0.5,ABS(Data!C57-(-5692))<0.5,ABS(Data!D57-(-2637))<0.5,ABS(Data!E57-(-1513))<0.5,ABS(Data!F57-(3929))<0.5) -> TRUE | C9: S-1: -1627, -5692, -2637, -1513, 3929
A10: cfi: formula equals S-1 reported total, all five periods | B10: =AND(ABS(Data!B62-(-2))<0.5,ABS(Data!C62-(-22))<0.5,ABS(Data!D62-(-3077))<0.5,ABS(Data!E62-(-49))<0.5,ABS(Data!F62-(-17181))<0.5) -> TRUE | C10: S-1: -2, -22, -3077, -49, -17181
A11: cff: formula equals S-1 reported total, all five periods | B11: =AND(ABS(Data!B70-(2320))<0.5,ABS(Data!C70-(7248))<0.5,ABS(Data!D70-(19960))<0.5,ABS(Data!E70-(4749))<0.5,ABS(Data!F70-(110774))<0.5) -> TRUE | C11: S-1: 2320, 7248, 19960, 4749, 110774
A12: aoi: formula equals S-1 reported total, all five periods | B12: =AND(ABS(Data!B40-(-522))<0.5,ABS(Data!C40-(-2788))<0.5,ABS(Data!D40-(-4854))<0.5,ABS(Data!E40-(-1849))<0.5,ABS(Data!F40-(1618))<0.5) -> TRUE | C12: S-1: -522, -2788, -4854, -1849, 1618
A13: adj_ni: formula equals S-1 reported total, all five periods | B13: =AND(ABS(Data!B41-(-457))<0.5,ABS(Data!C41-(-2683))<0.5,ABS(Data!D41-(-4448))<0.5,ABS(Data!E41-(-1741))<0.5,ABS(Data!F41-(2671))<0.5) -> TRUE | C13: S-1: -457, -2683, -4448, -1741, 2671
A14: EPS recomputed = reported EPS | B14: =AND(ABS(Data!B24-(-1.42))<0.01,ABS(Data!C24-(-5.43))<0.01,ABS(Data!D24-(-23.04))<0.01,ABS(Data!E24-(-7.25))<0.01,ABS(Data!F24-(-39.88))<0.01) -> TRUE
A15: Expenses by function total = expenses by nature total | B15: =AND(ABS(Data!$B$32-Data!$B$15)<0.5,ABS(Data!$C$32-Data!$C$15)<0.5,ABS(Data!$D$32-Data!$D$15)<0.5,ABS(Data!$E$32-Data!$E$15)<0.5,ABS(Data!$F$32-Data!$F$15)<0.5) -> TRUE
A16: US + International revenue = revenue | B16: =AND(ABS(Data!$B$8+Data!$B$9-Data!$B$7)<0.5,ABS(Data!$C$8+Data!$C$9-Data!$C$7)<0.5,ABS(Data!$D$8+Data!$D$9-Data!$D$7)<0.5,ABS(Data!$E$8+Data!$E$9-Data!$E$7)<0.5,ABS(Data!$F$8+Data!$F$9-Data!$F$7)<0.5) -> TRUE
A17: Cash flow net loss = income statement net loss | B17: =AND(ABS(Data!$B$45-Data!$B$22)<0.5,ABS(Data!$C$45-Data!$C$22)<0.5,ABS(Data!$D$45-Data!$D$22)<0.5,ABS(Data!$E$45-Data!$E$22)<0.5,ABS(Data!$F$45-Data!$F$22)<0.5) -> TRUE
A18: Cash flow ending cash = balance sheet cash + restricted cash | B18: =AND(ABS(Data!$C$74-Data!$B$104)<0.5,ABS(Data!$D$74-Data!$C$104)<0.5,ABS(Data!$F$74-Data!$D$104)<0.5) -> TRUE
A19: Balance sheet balances at all three dates | B19: =AND(ABS(Data!$B$88-Data!$B$102)<0.5,ABS(Data!$C$88-Data!$C$102)<0.5,ABS(Data!$D$88-Data!$D$102)<0.5) -> TRUE
A20: Total assets equal S-1 (7,752; 24,661; 147,358) | B20: =AND(ABS(Data!$B$88-7752)<0.5,ABS(Data!$C$88-24661)<0.5,ABS(Data!$D$88-147358)<0.5) -> TRUE
A21: Quarterly revenue sums to 6M2025, 6M2026 and FY2025 | B21: =AND(ABS(Data!$B$107+Data!$C$107-Data!$E$7)<0.5,ABS(Data!$F$107+Data!$G$107-Data!$F$7)<0.5,ABS(SUM(Data!$B$107:$E$107)-Data!$D$7)<0.5) -> TRUE
A22: Quarterly Adjusted Operating Income sums to half-years | B22: =AND(ABS(Data!$B$117+Data!$C$117-Data!$E$40)<0.5,ABS(Data!$F$117+Data!$G$117-Data!$F$40)<0.5) -> TRUE
A23: No formula errors on Data or Ratios | B23: =(SUMPRODUCT(--ISERROR(Data!B5:G177))+SUMPRODUCT(--ISERROR(Ratios!B5:G48)))=0 -> TRUE
A25: ALL CHECKS PASS | B25: =AND(B5:B23) -> TRUE
