Workbook

Sheet Historicals
A1: Historicals - as reported (blue) and derived by formula (black)
A2: USD millions unless stated. Q4-25 = FY25 - 9M-25; Q1-26 = H1-26 - Q2-26 where not reported. Every value is cited on the Sources sheet.
A4: Income statement (GAAP) | B4: Unit | C4: Q1-25 | D4: Q2-25 | E4: Q3-25 | F4: Q4-25 | G4: FY25 | H4: Q1-26 | I4: Q2-26 | J4: Q3-26 | K4: 9M-26 | L4: H1-25 | M4: 9M-25 | N4: H1-26 | O4: Sources (file p.)
A5: Revenue | B5: USD millions | C5: 4067 | D5: 4071 | E5: 5576 | F5: =$G$5-$M$5 -> 4960 | G5: 18674 | H5: 4694 | I5: 7814 | J5: 14575 | K5: 27083 | L5: 8138 | M5: 13714 | N5: 12508 | O5: S-1 p.36; Q2-26 release p.8; Q3-26 release p.9
A6: Cost of revenue | B6: USD millions | C6: =$L$6-$D$6 -> 1962 | D6: 2282 | E6: 2705 | F6: =$G$6-$M$6 -> 2502 | G6: 9451 | H6: =$N$6-$I$6 -> 2388 | I6: 3495 | J6: 5478 | K6: 11361 | L6: 4244 | M6: 6949 | N6: 5883 | O6: Q2-26 release p.8; Q3-26 release p.9; S-1 p.230
A7: Research and development | B7: USD millions | C7: =$L$7-$D$7 -> 1557 | D7: 1958 | E7: 2291 | F7: =$G$7-$M$7 -> 2837 | G7: 8643 | H7: =$N$7-$I$7 -> 3514 | I7: 3548 | J7: 4596 | K7: 11658 | L7: 3515 | M7: 5806 | N7: 7062 | O7: Q2-26 release p.8; Q3-26 release p.9; S-1 p.230
A8: Selling, general and administrative | B8: USD millions | C8: =$L$8-$D$8 -> 493 | D8: 606 | E8: 575 | F8: =$G$8-$M$8 -> 970 | G8: 2644 | H8: =$N$8-$I$8 -> 746 | I8: 912 | J8: 1707 | K8: 3365 | L8: 1099 | M8: 1674 | N8: 1658 | O8: Q2-26 release p.8; Q3-26 release p.9; S-1 p.230
A9: Restructuring charges (credits) | B9: USD millions | C9: =$L$9-$D$9 -> 4 | D9: 190 | E9: 278 | F9: =$G$9-$M$9 -> 15 | G9: 487 | H9: =$N$9-$I$9 -> -11 | I9: 2 | J9: 3 | K9: -6 | L9: 194 | M9: 472 | N9: -9 | O9: Q2-26 release p.8; Q3-26 release p.9; S-1 p.230
A10: Impairment | B10: USD millions | C10: =$L$10-$D$10 -> 24 | D10: 5 | E10: 0 | F10: =$G$10-$M$10 -> 9 | G10: 38 | H10: =$N$10-$I$10 -> 0 | I10: 0 | J10: 0 | K10: 0 | L10: 29 | M10: 29 | N10: 0 | O10: Q2-26 release p.8; Q3-26 release p.9; S-1 p.230
A11: Total costs and expenses | B11: USD millions | C11: 4040 | D11: 5041 | E11: 5849 | F11: =$G$11-$M$11 -> 6333 | G11: 21263 | H11: 6637 | I11: 7957 | J11: 11784 | K11: 26378 | L11: 9081 | M11: 14930 | N11: 14594 | O11: S-1 p.36; Q2-26 release p.8; Q3-26 release p.9
A12: Income (loss) from operations | B12: USD millions | C12: 27 | D12: -970 | E12: -273 | F12: =$G$12-$M$12 -> -1373 | G12: -2589 | H12: -1943 | I12: -143 | J12: 2791 | K12: 705 | L12: -943 | M12: -1216 | N12: -2086 | O12: S-1 p.36; Q2-26 release p.8; Q3-26 release p.9
A13: Interest expense | B13: USD millions | C13: =$L$13-$D$13 -> -447 | D13: -411 | E13: -514 | F13: =$G$13-$M$13 -> -573 | G13: -1945 | H13: =$N$13-$I$13 -> -664 | I13: -629 | J13: -675 | K13: -1968 | L13: -858 | M13: -1372 | N13: -1293 | O13: Q2-26 release p.8; Q3-26 release p.9; S-1 p.230
A14: Interest income | B14: USD millions | C14: =$L$14-$D$14 -> 117 | D14: 98 | E14: 155 | F14: =$G$14-$M$14 -> 122 | G14: 492 | H14: =$N$14-$I$14 -> 213 | I14: 340 | J14: 873 | K14: 1426 | L14: 215 | M14: 370 | N14: 553 | O14: Q2-26 release p.8; Q3-26 release p.9; S-1 p.231
A15: Other income (expense), net | B15: USD millions | C15: =$L$15-$D$15 -> -211 | D15: 413 | E15: 140 | F15: =$G$15-$M$15 -> -519 | G15: -177 | H15: =$N$15-$I$15 -> -1876 | I15: -86 | J15: 1025 | K15: -937 | L15: 202 | M15: 342 | N15: -1962 | O15: Q2-26 release p.8; Q3-26 release p.9; S-1 p.231
A16: Income (loss) before income taxes | B16: USD millions | C16: =$L$16-$D$16 -> -514 | D16: -870 | E16: -492 | F16: =$G$16-$M$16 -> -2343 | G16: -4219 | H16: =$N$16-$I$16 -> -4270 | I16: -518 | J16: 4014 | K16: -774 | L16: -1384 | M16: -1876 | N16: -4788 | O16: Q2-26 release p.8; Q3-26 release p.9; S-1 p.231
A17: Provision for (benefit from) income taxes | B17: USD millions | C17: =$L$17-$D$17 -> 14 | D17: 138 | E17: 562 | F17: =$G$17-$M$17 -> 4 | G17: 718 | H17: =$N$17-$I$17 -> 6 | I17: 23 | J17: -390 | K17: -361 | L17: 152 | M17: 714 | N17: 29 | O17: Q2-26 release p.8; Q3-26 release p.9; S-1 p.231
A18: Net income (loss) | B18: USD millions | C18: -528 | D18: -1008 | E18: -1054 | F18: =$G$18-$M$18 -> -2347 | G18: -4937 | H18: -4276 | I18: -541 | J18: 4404 | K18: -413 | L18: -1536 | M18: -2590 | N18: -4817 | O18: S-1 p.36; Q2-26 release p.8; Q3-26 release p.9
A19: Net income (loss) to common shareholders | B19: USD millions | C19: =$L$19-$D$19 -> -528 | D19: -1008 | E19: -1054 | F19: =$G$19-$M$19 -> -2347 | G19: -4937 | H19: =$N$19-$I$19 -> -4947 | I19: -541 | J19: 4404 | K19: -1084 | L19: -1536 | M19: -2590 | N19: -5488 | O19: Q2-26 release p.8; Q3-26 release p.9; S-1 p.231
A20: EPS, basic ($) | B20: USD per share | C20: -0.18 | D20: -0.34 | E20: -0.36 | G20: -1.69 | H20: -1.27 | I20: -0.09 | J20: 0.37 | K20: -0.15 | L20: -0.53 | M20: -0.89 | N20: -1.12 | O20: S-1 p.36; Q2-26 release p.8; Q3-26 release p.9
A21: EPS, diluted ($) | B21: USD per share | C21: -0.18 | D21: -0.34 | E21: -0.36 | G21: -1.69 | H21: -1.27 | I21: -0.09 | J21: 0.35 | K21: -0.15 | L21: -0.53 | M21: -0.89 | N21: -1.12 | O21: S-1 p.36; Q2-26 release p.8; Q3-26 release p.9
A22: Weighted average shares, basic (M) | B22: millions | C22: 2875 | D22: 2929 | E22: 2941 | G22: 2926 | H22: 3884 | I22: 5864 | J22: 11942 | K22: 7274 | L22: 2902 | M22: 2915 | N22: 4879 | O22: S-1 p.36; Q2-26 release p.8; Q3-26 release p.9
A23: Weighted average shares, diluted (M) | B23: millions | C23: 2875 | D23: 2929 | E23: 2941 | G23: 2926 | H23: 3884 | I23: 5864 | J23: 12475 | K23: 7274 | L23: 2902 | M23: 2915 | N23: 4879 | O23: S-1 p.36; Q2-26 release p.8; Q3-26 release p.9
A25: Net income to Adjusted EBITDA (non-GAAP reconciliation) | B25: Unit | C25: Q1-25 | D25: Q2-25 | E25: Q3-25 | F25: Q4-25 | G25: FY25 | H25: Q1-26 | I25: Q2-26 | J25: Q3-26 | K25: 9M-26 | L25: H1-25 | M25: 9M-25 | N25: H1-26 | O25: Sources (file p.)
A26: Net income (loss) | B26: USD millions | C26: -528 | D26: -1008 | E26: -1054 | F26: =$G$26-$M$26 -> -2347 | G26: -4937 | H26: -4276 | I26: -541 | J26: 4404 | K26: -413 | L26: -1536 | M26: -2590 | N26: -4817 | O26: S-1 p.109; Q2-26 release p.8; Q3-26 release p.10
A27: + Depreciation and amortisation | B27: USD millions | C27: 1443 | D27: 1526 | E27: 1814 | F27: =$G$27-$M$27 -> 1917 | G27: 6701 | H27: 2442 | I27: 2848 | J27: 3644 | K27: 8934 | L27: 2970 | M27: 4784 | N27: 5290 | O27: S-1 p.109; Q2-26 release p.8; Q3-26 release p.10
A28: + Share-based compensation | B28: USD millions | C28: 232 | D28: 463 | E28: 350 | F28: =$G$28-$M$28 -> 903 | G28: 1947 | H28: 639 | I28: 831 | J28: 1146 | K28: 2616 | L28: 694 | M28: 1044 | N28: 1470 | O28: S-1 p.109; Q2-26 release p.8; Q3-26 release p.10
A29: + SBC related to acquisitions | B29: USD millions | C29: 0 | D29: 0 | E29: 0 | F29: =$G$29-$M$29 -> 0 | G29: 0 | H29: 0 | I29: 0 | J29: 1217 | K29: 1217 | L29: 0 | M29: 0 | N29: 0 | O29: S-1 p.109; Q2-26 release p.8; Q3-26 release p.10
A30: + Acquisition-related costs | B30: USD millions | C30: 0 | D30: 0 | E30: 0 | F30: =$G$30-$M$30 -> 0 | G30: 0 | H30: 0 | I30: 0 | J30: 8 | K30: 8 | L30: 0 | M30: 0 | N30: 0 | O30: S-1 p.109; Q2-26 release p.8; Q3-26 release p.10
A31: + Restructuring charges | B31: USD millions | C31: 4 | D31: 190 | E31: 278 | F31: =$G$31-$M$31 -> 15 | G31: 487 | H31: -11 | I31: 2 | J31: 3 | K31: -6 | L31: 194 | M31: 472 | N31: -9 | O31: S-1 p.109; Q2-26 release p.8; Q3-26 release p.10
A32: + Impairments | B32: USD millions | C32: 24 | D32: 5 | E32: 0 | F32: =$G$32-$M$32 -> 9 | G32: 38 | H32: 0 | I32: 0 | J32: 0 | K32: 0 | L32: 29 | M32: 29 | N32: 0 | O32: S-1 p.109; Q2-26 release p.8; Q3-26 release p.10
A33: + Interest expense | B33: USD millions | C33: 447 | D33: 411 | E33: 514 | F33: =$G$33-$M$33 -> 573 | G33: 1945 | H33: 664 | I33: 629 | J33: 675 | K33: 1968 | L33: 858 | M33: 1372 | N33: 1293 | O33: S-1 p.109; Q2-26 release p.8; Q3-26 release p.10
A34: - Interest income | B34: USD millions | C34: -117 | D34: -98 | E34: -155 | F34: =$G$34-$M$34 -> -122 | G34: -492 | H34: -213 | I34: -340 | J34: -873 | K34: -1426 | L34: -215 | M34: -370 | N34: -553 | O34: S-1 p.109; Q2-26 release p.8; Q3-26 release p.10
A35: + Other (income) expense, net | B35: USD millions | C35: 211 | D35: -413 | E35: -140 | F35: =$G$35-$M$35 -> 519 | G35: 177 | H35: 1876 | I35: 86 | J35: -1025 | K35: 937 | L35: -202 | M35: -342 | N35: 1962 | O35: S-1 p.109; Q2-26 release p.8; Q3-26 release p.10
A36: + Provision for (benefit from) income taxes | B36: USD millions | C36: 14 | D36: 138 | E36: 562 | F36: =$G$36-$M$36 -> 4 | G36: 718 | H36: 6 | I36: 23 | J36: -390 | K36: -361 | L36: 152 | M36: 714 | N36: 29 | O36: S-1 p.109; Q2-26 release p.8; Q3-26 release p.10
A37: Adjusted EBITDA (non-GAAP) | B37: USD millions | C37: 1730 | D37: 1214 | E37: 2169 | F37: =$G$37-$M$37 -> 1471 | G37: 6584 | H37: 1127 | I37: 3538 | J37: 8809 | K37: 13474 | L37: 2944 | M37: 5113 | N37: 4665 | O37: S-1 p.109; Q2-26 release p.8; Q3-26 release p.10
A39: Segments (Segment Adjusted EBITDA is non-GAAP) | B39: Unit | C39: Q1-25 | D39: Q2-25 | E39: Q3-25 | F39: Q4-25 | G39: FY25 | H39: Q1-26 | I39: Q2-26 | J39: Q3-26 | K39: 9M-26 | L39: H1-25 | M39: 9M-25 | N39: H1-26 | O39: Sources (file p.)
A40: Space: launch services revenue | B40: count | C40: =$L$40-$D$40 -> 566 | D40: 490 | E40: 1000 | F40: =$G$40-$M$40 -> 520 | G40: 2576 | H40: 330 | I40: 648 | J40: 1130 | K40: 2108 | L40: 1056 | M40: 2056 | N40: 978 | O40: Q2-26 release p.4; Q3-26 release p.4; S-1 p.243
A41: Space: launch & development revenue | B41: count | C41: =$L$41-$D$41 -> 299 | D41: 256 | E41: 666 | F41: =$G$41-$M$41 -> 289 | G41: 1510 | H41: 289 | I41: 314 | J41: 637 | K41: 1240 | L41: 555 | M41: 1221 | N41: 603 | O41: Q2-26 release p.4; Q3-26 release p.4; S-1 p.243
A42: Space: revenue | B42: USD millions | C42: =$L$42-$D$42 -> 865 | D42: 746 | E42: 1666 | F42: =$G$42-$M$42 -> 809 | G42: 4086 | H42: 619 | I42: 962 | J42: 1767 | K42: 3348 | L42: 1611 | M42: 3277 | N42: 1581 | O42: Q2-26 release p.3; Q3-26 release p.3; S-1 p.269
A43: Space: cost of revenue | B43: USD millions | C43: =$L$43-$D$43 -> 297 | D43: 330 | E43: 477 | F43: =$G$43-$M$43 -> 248 | G43: 1352 | H43: 281 | I43: 329 | J43: 435 | K43: 1045 | L43: 627 | M43: 1104 | N43: 610 | O43: Q2-26 release p.4; Q3-26 release p.4; S-1 p.269
...

Sheet Ratios
A1: Ratios - by quarter, formula shown
A2: IC = debt & finance leases + redeemable preferred + equity - cash - marketable securities. Mar-26 debt excludes finance leases (not disclosed). n/a = input not available.
A3: Input: tax rate used in ROIC (US federal statutory rate) | E3: 0.21
A4: Group | B4: Ratio | C4: Basis | D4: Formula | E4: Q1-25 | F4: Q2-25 | G4: Q3-25 | H4: Q4-25 | I4: Q1-26 | J4: Q2-26 | K4: Q3-26 | L4: FY25 | M4: 9M-26
A5: Growth | B5: Revenue growth YoY | C5: GAAP | D5: Revenue / revenue same quarter prior year - 1 | E5: n/a | F5: n/a | G5: n/a | H5: n/a | I5: =Historicals!$H$5/Historicals!$C$5-1 -> 0.15416769 | J5: =Historicals!$I$5/Historicals!$D$5-1 -> 0.91943012 | K5: =Historicals!$J$5/Historicals!$E$5-1 -> 1.6138809 | L5: n/a | M5: n/a
A6: Growth | B6: Revenue growth QoQ | C6: GAAP | D6: Revenue / revenue prior quarter - 1 | E6: n/a | F6: =Historicals!$D$5/Historicals!$C$5-1 -> 0.00098352594 | G6: =Historicals!$E$5/Historicals!$D$5-1 -> 0.36968804 | H6: =Historicals!$F$5/Historicals!$E$5-1 -> -0.11047346 | I6: =Historicals!$H$5/Historicals!$F$5-1 -> -0.053629032 | J6: =Historicals!$I$5/Historicals!$H$5-1 -> 0.66467831 | K6: =Historicals!$J$5/Historicals!$I$5-1 -> 0.86524187 | L6: n/a | M6: n/a
B7: Revenue grew 15%, 92% and 161% YoY in Q1-Q3 2026; the acceleration came from SI, whose revenue rose from $0.8B in Q1 to $7.6B in Q3.
B8: Excluding SI, Q3 revenue (Space + Connectivity) grew 47% YoY: fast, but well below the 161% headline.
A10: Profitability | B10: Gross margin | C10: GAAP | D10: (Revenue - cost of revenue) / revenue | E10: =(Historicals!$C$5-Historicals!$C$6)/Historicals!$C$5 -> 0.51758053 | F10: =(Historicals!$D$5-Historicals!$D$6)/Historicals!$D$5 -> 0.43944977 | G10: =(Historicals!$E$5-Historicals!$E$6)/Historicals!$E$5 -> 0.51488522 | H10: =(Historicals!$F$5-Historicals!$F$6)/Historicals!$F$5 -> 0.49556452 | I10: =(Historicals!$H$5-Historicals!$H$6)/Historicals!$H$5 -> 0.49126545 | J10: =(Historicals!$I$5-Historicals!$I$6)/Historicals!$I$5 -> 0.55272588 | K10: =(Historicals!$J$5-Historicals!$J$6)/Historicals!$J$5 -> 0.62415094 | L10: =(Historicals!$G$5-Historicals!$G$6)/Historicals!$G$5 -> 0.49389526 | M10: =(Historicals!$K$5-Historicals!$K$6)/Historicals!$K$5 -> 0.58051176
A11: Profitability | B11: Adjusted EBITDA margin (as reported) | C11: non-GAAP | D11: Adjusted EBITDA / revenue | E11: =Historicals!$C$37/Historicals!$C$5 -> 0.42537497 | F11: =Historicals!$D$37/Historicals!$D$5 -> 0.29820683 | G11: =Historicals!$E$37/Historicals!$E$5 -> 0.38898852 | H11: =Historicals!$F$37/Historicals!$F$5 -> 0.29657258 | I11: =Historicals!$H$37/Historicals!$H$5 -> 0.24009374 | J11: =Historicals!$I$37/Historicals!$I$5 -> 0.45277707 | K11: =Historicals!$J$37/Historicals!$J$5 -> 0.60439108 | L11: =Historicals!$G$37/Historicals!$G$5 -> 0.35257577 | M11: =Historicals!$K$37/Historicals!$K$5 -> 0.49750766
A12: Profitability | B12: Adjusted EBITDA margin (pre-Q3 definition) | C12: non-GAAP | D12: (Adj. EBITDA - acquisition SBC - acquisition costs) / revenue | E12: =(Historicals!$C$37-Historicals!$C$29-Historicals!$C$30)/Historicals!$C$5 -> 0.42537497 | F12: =(Historicals!$D$37-Historicals!$D$29-Historicals!$D$30)/Historicals!$D$5 -> 0.29820683 | G12: =(Historicals!$E$37-Historicals!$E$29-Historicals!$E$30)/Historicals!$E$5 -> 0.38898852 | H12: =(Historicals!$F$37-Historicals!$F$29-Historicals!$F$30)/Historicals!$F$5 -> 0.29657258 | I12: =(Historicals!$H$37-Historicals!$H$29-Historicals!$H$30)/Historicals!$H$5 -> 0.24009374 | J12: =(Historicals!$I$37-Historicals!$I$29-Historicals!$I$30)/Historicals!$I$5 -> 0.45277707 | K12: =(Historicals!$J$37-Historicals!$J$29-Historicals!$J$30)/Historicals!$J$5 -> 0.52034305 | L12: =(Historicals!$G$37-Historicals!$G$29-Historicals!$G$30)/Historicals!$G$5 -> 0.35257577 | M12: =(Historicals!$K$37-Historicals!$K$29-Historicals!$K$30)/Historicals!$K$5 -> 0.45227634
A13: Profitability | B13: Operating margin | C13: GAAP | D13: Income (loss) from operations / revenue | E13: =Historicals!$C$12/Historicals!$C$5 -> 0.0066388001 | F13: =Historicals!$D$12/Historicals!$D$5 -> -0.2382707 | G13: =Historicals!$E$12/Historicals!$E$5 -> -0.048959828 | H13: =Historicals!$F$12/Historicals!$F$5 -> -0.27681452 | I13: =Historicals!$H$12/Historicals!$H$5 -> -0.41393268 | J13: =Historicals!$I$12/Historicals!$I$5 -> -0.018300486 | K13: =Historicals!$J$12/Historicals!$J$5 -> 0.19149228 | L13: =Historicals!$G$12/Historicals!$G$5 -> -0.13864196 | M13: =Historicals!$K$12/Historicals!$K$5 -> 0.02603109
A14: Profitability | B14: Net margin | C14: GAAP | D14: Net income (loss) / revenue | E14: =Historicals!$C$18/Historicals!$C$5 -> -0.12982542 | F14: =Historicals!$D$18/Historicals!$D$5 -> -0.24760501 | G14: =Historicals!$E$18/Historicals!$E$5 -> -0.18902439 | H14: =Historicals!$F$18/Historicals!$F$5 -> -0.47318548 | I14: =Historicals!$H$18/Historicals!$H$5 -> -0.91095015 | J14: =Historicals!$I$18/Historicals!$I$5 -> -0.069234707 | K14: =Historicals!$J$18/Historicals!$J$5 -> 0.30216123 | L14: =Historicals!$G$18/Historicals!$G$5 -> -0.26437828 | M14: =Historicals!$K$18/Historicals!$K$5 -> -0.015249418
A15: Profitability | B15: ROIC (annualised) | C15: GAAP | D15: Op. income x (1 - tax) x 4 / average IC (FY: x 1) | E15: n/a | F15: n/a | G15: n/a | H15: n/a | I15: =Historicals!$H$12*(1-Ratios!$E$3)*4/((((Historicals!$D$159+Historicals!$D$163)+Historicals!$D$166+Historicals!$D$171-(Historicals!$D$143+Historicals!$D$144))+(Historicals!$E$182+Historicals!$E$166+Historicals!$E$171-(Historicals!$E$143+Historicals!$E$144)))/2) -> -0.14197567 | J15: =Historicals!$I$12*(1-Ratios!$E$3)*4/(((Historicals!$E$182+Historicals!$E$166+Historicals!$E$171-(Historicals!$E$143+Historicals!$E$144))+((Historicals!$F$159+Historicals!$F$163)+Historicals!$F$166+Historicals!$F$171-(Historicals!$F$143+Historicals!$F$144)))/2) -> -0.0079558439 | K15: =Historicals!$J$12*(1-Ratios!$E$3)*4/((((Historicals!$F$159+Historicals!$F$163)+Historicals!$F$166+Historicals!$F$171-(Historicals!$F$143+Historicals!$F$144))+((Historicals!$G$159+Historicals!$G$163)+Historicals!$G$166+Historicals!$G$171-(Historicals!$G$143+Historicals!$G$144)))/2) -> 0.091709924 | L15: =Historicals!$G$12*(1-Ratios!$E$3)*1/((((Historicals!$C$159+Historicals!$C$163)+Historicals!$C$166+Historicals!$C$171-(Historicals!$C$143+Historicals!$C$144))+((Historicals!$D$159+Historicals!$D$163)+Historicals!$D$166+Historicals!$D$171-(Historicals!$D$143+Historicals!$D$144)))/2) -> -0.06115809 | M15: n/a
B16: Operating margin turned from -41% in Q1-26 to +19% in Q3-26, and Adjusted EBITDA margin from 24% to 60% (52% on the pre-Q3 definition).
B17: Q3 net income includes $1.0B of other income, $0.9B of interest income and a $0.4B tax benefit; ROIC was positive only in Q3, when invested capital roughly doubled with the Cursor acquisition.
A19: Cash flow | B19: Free cash flow ($M) | C19: GAAP | D19: Cash from operations - purchases of PP&E | E19: =(Historicals!$C$112+Historicals!$C$113) -> -3413 | F19: =(Historicals!$D$112+Historicals!$D$113) -> -3201 | G19: =(Historicals!$E$112+Historicals!$E$113) -> -3111 | H19: =(Historicals!$F$112+Historicals!$F$113) -> -4226 | I19: =(Historicals!$H$112+Historicals!$H$113) -> -9060 | J19: =(Historicals!$I$112+Historicals!$I$113) -> -15950 | K19: =(Historicals!$J$112+Historicals!$J$113) -> -9962 | L19: =(Historicals!$G$112+Historicals!$G$113) -> -13952 | M19: =(Historicals!$K$112+Historicals!$K$113) -> -34972
A20: Cash flow | B20: FCF margin | C20: GAAP | D20: FCF / revenue | E20: =(Historicals!$C$112+Historicals!$C$113)/Historicals!$C$5 -> -0.83919351 | F20: =(Historicals!$D$112+Historicals!$D$113)/Historicals!$D$5 -> -0.78629329 | G20: =(Historicals!$E$112+Historicals!$E$113)/Historicals!$E$5 -> -0.55792683 | H20: =(Historicals!$F$112+Historicals!$F$113)/Historicals!$F$5 -> -0.85201613 | I20: =(Historicals!$H$112+Historicals!$H$113)/Historicals!$H$5 -> -1.9301236 | J20: =(Historicals!$I$112+Historicals!$I$113)/Historicals!$I$5 -> -2.0412081 | K20: =(Historicals!$J$112+Historicals!$J$113)/Historicals!$J$5 -> -0.68349914 | L20: =(Historicals!$G$112+Historicals!$G$113)/Historicals!$G$5 -> -0.74713505 | M20: =(Historicals!$K$112+Historicals!$K$113)/Historicals!$K$5 -> -1.2912897
A21: Cash flow | B21: FCF / Adjusted EBITDA | C21: mixed | D21: FCF / Adjusted EBITDA (as reported) | E21: =(Historicals!$C$112+Historicals!$C$113)/Historicals!$C$37 -> -1.9728324 | F21: =(Historicals!$D$112+Historicals!$D$113)/Historicals!$D$37 -> -2.6367381 | G21: =(Historicals!$E$112+Historicals!$E$113)/Historicals!$E$37 -> -1.4343015 | H21: =(Historicals!$F$112+Historicals!$F$113)/Historicals!$F$37 -> -2.8728756 | I21: =(Historicals!$H$112+Historicals!$H$113)/Historicals!$H$37 -> -8.0390417 | J21: =(Historicals!$I$112+Historicals!$I$113)/Historicals!$I$37 -> -4.5081967 | K21: =(Historicals!$J$112+Historicals!$J$113)/Historicals!$J$37 -> -1.1308889 | L21: =(Historicals!$G$112+Historicals!$G$113)/Historicals!$G$37 -> -2.1190765 | M21: =(Historicals!$K$112+Historicals!$K$113)/Historicals!$K$37 -> -2.5955173
A22: Cash flow | B22: Cash runway (quarters) | C22: GAAP | D22: (Cash + marketable securities, quarter end) / -FCF of the quarter; n/a if FCF >= 0 | E22: n/a | F22: n/a | G22: n/a | H22: =IF((Historicals!$F$112+Historicals!$F$113)<0,(Historicals!$D$143+Historicals!$D$144)/-(Historicals!$F$112+Historicals!$F$113),"n/a") -> 5.8558921 | I22: =IF((Historicals!$H$112+Historicals!$H$113)<0,(Historicals!$E$143+Historicals!$E$144)/-(Historicals!$H$112+Historicals!$H$113),"n/a") -> 2.6131347 | J22: =IF((Historicals!$I$112+Historicals!$I$113)<0,(Historicals!$F$143+Historicals!$F$144)/-(Historicals!$I$112+Historicals!$I$113),"n/a") -> 6.2701567 | K22: =IF((Historicals!$J$112+Historicals!$J$113)<0,(Historicals!$G$143+Historicals!$G$144)/-(Historicals!$J$112+Historicals!$J$113),"n/a") -> 9.0197751 | L22: n/a | M22: n/a
B23: FCF was negative in every 2026 quarter (-$9.1B, -$16.0B, -$10.0B) because capex outran operating cash flow.
B24: Cash and securities of $89.9B at Sep-26 equal about nine quarters of the Q3 cash outflow.
A26: Capex | B26: Capex / revenue | C26: GAAP | D26: Purchases of PP&E / revenue | E26: =-Historicals!$C$113/Historicals!$C$5 -> 1.0179493 | F26: =-Historicals!$D$113/Historicals!$D$5 -> 0.69393269 | G26: =-Historicals!$E$113/Historicals!$E$5 -> 1.2338594 | H26: =-Historicals!$F$113/Historicals!$F$5 -> 1.3893145 | I26: =-Historicals!$H$113/Historicals!$H$5 -> 2.1531743 | J26: =-Historicals!$I$113/Historicals!$I$5 -> 2.3507807 | K26: =-Historicals!$J$113/Historicals!$J$5 -> 1.3442882 | L26: =-Historicals!$G$113/Historicals!$G$5 -> 1.1104745 | M26: =-Historicals!$K$113/Historicals!$K$5 -> 1.7748772
A27: Capex | B27: Capex / D&A | C27: GAAP | D27: Purchases of PP&E / D&A | E27: =-Historicals!$C$113/Historicals!$C$27 -> 2.8690229 | F27: =-Historicals!$D$113/Historicals!$D$27 -> 1.8512451 | G27: =-Historicals!$E$113/Historicals!$E$27 -> 3.7927233 | H27: =-Historicals!$F$113/Historicals!$F$27 -> 3.5946792 | I27: =-Historicals!$H$113/Historicals!$H$27 -> 4.1388206 | J27: =-Historicals!$I$113/Historicals!$I$27 -> 6.4497893 | K27: =-Historicals!$J$113/Historicals!$J$27 -> 5.3767838 | L27: =-Historicals!$G$113/Historicals!$G$27 -> 3.0946127 | M27: =-Historicals!$K$113/Historicals!$K$27 -> 5.3804567
B28: Capex exceeded revenue in every 2026 quarter (2.2x, 2.4x, 1.3x); SI accounted for 83% of 9M-26 capex.
B29: Capex ran at 4.1-6.5x D&A in 2026; net PP&E rose from $42.6B at Dec-25 to $89.5B at Sep-26.
A31: Leverage | B31: Net debt ($M; negative = net cash) | C31: GAAP | D31: Debt & finance leases - cash - marketable securities | E31: n/a | F31: n/a | G31: n/a | H31: =(Historicals!$D$159+Historicals!$D$163)-(Historicals!$D$143+Historicals!$D$144) -> -1851 | I31: =Historicals!$E$182-(Historicals!$E$143+Historicals!$E$144) -> 5436 | J31: =(Historicals!$F$159+Historicals!$F$163)-(Historicals!$F$143+Historicals!$F$144) -> -60645 | K31: =(Historicals!$G$159+Historicals!$G$163)-(Historicals!$G$143+Historicals!$G$144) -> -51011 | L31: =(Historicals!$D$159+Historicals!$D$163)-(Historicals!$D$143+Historicals!$D$144) -> -1851 | M31: n/a
A32: Leverage | B32: Net debt / LTM Adjusted EBITDA | C32: mixed | D32: Net debt / last-twelve-month Adj. EBITDA | E32: n/a | F32: n/a | G32: n/a | H32: =((Historicals!$D$159+Historicals!$D$163)-(Historicals!$D$143+Historicals!$D$144))/Historicals!$G$37 -> -0.28113609 | I32: =(Historicals!$E$182-(Historicals!$E$143+Historicals!$E$144))/(Historicals!$G$37-(Historicals!$C$37)+(Historicals!$H$37)) -> 0.90887811 | J32: =((Historicals!$F$159+Historicals!$F$163)-(Historicals!$F$143+Historicals!$F$144))/(Historicals!$G$37-(Historicals!$C$37+Historicals!$D$37)+(Historicals!$H$37+Historicals!$I$37)) -> -7.3022276 | K32: =((Historicals!$G$159+Historicals!$G$163)-(Historicals!$G$143+Historicals!$G$144))/(Historicals!$G$37-(Historicals!$C$37+Historicals!$D$37+Historicals!$E$37)+(Historicals!$H$37+Historicals!$I$37+Historicals!$J$37)) -> -3.4132486 | L32: =((Historicals!$D$159+Historicals!$D$163)-(Historicals!$D$143+Historicals!$D$144))/Historicals!$G$37 -> -0.28113609 | M32: n/a
A33: Leverage | B33: Interest coverage (EBIT) | C33: GAAP | D33: Income (loss) from operations / interest expense | E33: =Historicals!$C$12/-Historicals!$C$13 -> 0.060402685 | F33: =Historicals!$D$12/-Historicals!$D$13 -> -2.3600973 | G33: =Historicals!$E$12/-Historicals!$E$13 -> -0.5311284 | H33: =Historicals!$F$12/-Historicals!$F$13 -> -2.3961606 | I33: =Historicals!$H$12/-Historicals!$H$13 -> -2.9262048 | J33: =Historicals!$I$12/-Historicals!$I$13 -> -0.22734499 | K33: =Historicals!$J$12/-Historicals!$J$13 -> 4.1348148 | L33: =Historicals!$G$12/-Historicals!$G$13 -> -1.3311054 | M33: =Historicals!$K$12/-Historicals!$K$13 -> 0.35823171
A34: Leverage | B34: Interest coverage (Adj. EBITDA) | C34: non-GAAP | D34: Adjusted EBITDA / interest expense | E34: =Historicals!$C$37/-Historicals!$C$13 -> 3.8702461 | F34: =Historicals!$D$37/-Historicals!$D$13 -> 2.9537713 | G34: =Historicals!$E$37/-Historicals!$E$13 -> 4.2198444 | H34: =Historicals!$F$37/-Historicals!$F$13 -> 2.5671902 | I34: =Historicals!$H$37/-Historicals!$H$13 -> 1.6972892 | J34: =Historicals!$I$37/-Historicals!$I$13 -> 5.6248013 | K34: =Historicals!$J$37/-Historicals!$J$13 -> 13.05037 | L34: =Historicals!$G$37/-Historicals!$G$13 -> 3.38509 | M34: =Historicals!$K$37/-Historicals!$K$13 -> 6.8465447
A35: Leverage | B35: Current ratio | C35: GAAP | D35: Current assets / current liabilities (quarter end) | E35: n/a | F35: n/a | G35: n/a | H35: =Historicals!$D$148/Historicals!$D$161 -> 1.4463551 | I35: =Historicals!$E$148/Historicals!$E$161 -> 1.2167294 | J35: =Historicals!$F$148/Historicals!$F$161 -> 5.1153773 | K35: =Historicals!$G$148/Historicals!$G$161 -> 3.0843362 | L35: =Historicals!$D$148/Historicals!$D$161 -> 1.4463551 | M35: n/a
B36: The company holds net cash ($51.0B at Sep-26) after the $85.7B IPO and $25B bond, so net debt/EBITDA is negative.
B37: EBIT covered interest 4.1x in Q3, against less than 0.1x in every earlier quarter; the 3.1x current ratio at Sep-26 includes the IPO proceeds.

Sheet Sources
A1: Sources, data gaps, and value-level citations
A3: Source ID | B3: File / URL | C3: Description | D3: Date
A4: S-1 | B4: filings/Space Exploration Technologies - S-1.pdf | C4: Form S-1 registration statement (browser print, 272 PDF pages; truncated at F-60) | D4: Filed 20 May 2026
A5: Q2-26 release | B5: filings/SpaceX-Reports-Second-Quarter-2026-Results.pdf | C5: Q2 2026 results release (10 pages) | D5: Aug 2026
A6: Q3-26 release | B6: filings/SpaceX-Reports-Third-Quarter-2026-Results.pdf | C6: Q3 2026 results release (13 pages) | D6: 20 Oct 2026
A7: Page numbers are PDF page numbers. Index of S-1 sections: text/INDEX.md.
A9: Gaps and data issues | B9: Period | C9: Status | D9: Detail | E9: Consequence
A10: Q1-26 full income statement and cash flow statement | B10: Q1-26 | C10: derived | D10: S-1 PDF is truncated at F-60; interim statements (F-63 to F-69) missing. IS lines derived as H1-26 (Q2 release p.8) minus Q2-26; totals tie to S-1 summary p.36 and reconciliation p.109. | E10: None for IS; CF available only as CFO/CFI/CFF totals and capex.
A11: Q1-26 balance sheet detail (receivables; inventory; payables; deferred revenue; intangibles; goodwill; long-term debt line) | B11: Mar-26 | C11: N/A - not found | D11: S-1 summary p.37 gives only cash, current assets, PP&E, total assets, current debt, current liabilities, total liabilities, preferred, equity. Marketable securities from p.111; debt from capitalization table p.71. | E11: Working-capital ratios not computed for Mar-26.
A12: Finance lease liability | B12: Mar-26 | C12: N/A - not found | D12: Capitalization table p.71 shows debt excluding finance leases ($29.111B net). | E12: Mar-26 net debt uses debt excluding finance leases.
A13: Debt composition (bridge loan; notes; other financings) | B13: Jun-26 and Sep-26 | C13: N/A - not found | D13: Releases give only balance-sheet totals of debt and finance leases. Q2 p.7 confirms $25B notes issued 26 Jun 2026 at 5.855% weighted coupon. | E13: Cost of debt must rely on coupon of new notes plus external yield data.
A14: Standalone quarterly cash-flow line items (working capital; D&A in CF; financing detail) | B14: Q1-26 to Q3-26 | C14: N/A - not found | D14: Q2 release gives only H1 CFO/CFI/CFF totals; Q3 gives 9M detail. Standalone quarters derived for CFO, CFI, CFF and capex only. | E14: Quarterly FCF uses CFO minus capex.
A15: Starlink ARPU | B15: Q4-25 | C15: N/A - not found | D15: FY25 ARPU ($81) is a full-year figure and cannot be split. | E15: Q4-25 ARPU blank.
A16: EPS and weighted average shares | B16: Q4-25 | C16: N/A - not found | D16: Not derivable from annual and nine-month figures. | E16: Q4-25 EPS blank.
A17: Backlog | B17: Mar-26 and Sep-26 | C17: N/A - not found | D17: Backlog reported only at 31 Dec 2025 ($28.377B; S-1 p.243) and 30 Jun 2026 ($47.5B; Q2 p.1). | E17: Backlog series has two points.
A18: Starlink subscribers FY25 (8.9M) | B18: Dec-25 | C18: low confidence | D18: Only source is S-1 p.37 table row clipped by a page break; digits read from visible upper half. Q1 values confirmed in text p.86. | E18: Flagged in Sources.
A19: Class A shares outstanding | B19: Dec-25 | C19: inconsistent | D19: S-1 p.230 shows 1954M; Q2 p.9 and Q3 p.11 comparatives show 1952M. Releases used. | E19: Immaterial.
A20: 2025 segment figures | B20: Q1-25 to Q3-25 | C20: minor differences | D20: $2M differences between S-1, Q2 and Q3 releases in Space/SI Adj. EBITDA, SI D&A and SI SBC; offsets cancel at consolidated level. Reported figure used for each quarter. | E20: Immaterial.
... A24: Item (Historicals) | B24: Period | C24: Value in model | D24: Method | E24: Source (file p.)
A25: Accounts payable | B25: Dec-25 | C25: =Historicals!$D$157 -> 11792 | D25: reported | E25: Q2-26 release p.9; Q3-26 release p.11; S-1 p.230
A26: Accounts payable | B26: Jun-26 | C26: =Historicals!$F$157 -> 8243 | D26: reported | E26: Q2-26 release p.9
A27: Accounts payable | B27: Sep-26 | C27: =Historicals!$G$157 -> 13259 | D27: reported | E27: Q3-26 release p.11
A28: Accounts receivable | B28: Dec-25 | C28: =Historicals!$D$145 -> 1579 | D28: reported | E28: Q2-26 release p.9; Q3-26 release p.11; S-1 p.230
A29: Accounts receivable | B29: Jun-26 | C29: =Historicals!$F$145 -> 3596 | D29: reported | E29: Q2-26 release p.9
A30: Accounts receivable | B30: Sep-26 | C30: =Historicals!$G$145 -> 4772 | D30: reported | E30: Q3-26 release p.11
A31: Accrued other current | B31: Dec-25 | C31: =Historicals!$D$160 -> 2569 | D31: reported | E31: Q2-26 release p.9; Q3-26 release p.11; S-1 p.230
A32: Accrued other current | B32: Jun-26 | C32: =Historicals!$F$160 -> 2377 | D32: reported | E32: Q2-26 release p.9
A33: Accrued other current | B33: Sep-26 | C33: =Historicals!$G$160 -> 5997 | D33: reported | E33: Q3-26 release p.11
A34: Accumulated deficit | B34: Dec-25 | C34: =Historicals!$D$169 -> -37035 | D34: reported | E34: Q2-26 release p.9; Q3-26 release p.11; S-1 p.230
A35: Accumulated deficit | B35: Jun-26 | C35: =Historicals!$F$169 -> -41852 | D35: reported | E35: Q2-26 release p.9
A36: Accumulated deficit | B36: Sep-26 | C36: =Historicals!$G$169 -> -37448 | D36: reported | E36: Q3-26 release p.11
A37: Aoci | B37: Dec-25 | C37: =Historicals!$D$170 -> 1898 | D37: reported | E37: Q2-26 release p.9; Q3-26 release p.11; S-1 p.230
A38: Aoci | B38: Jun-26 | C38: =Historicals!$F$170 -> 1719 | D38: reported | E38: Q2-26 release p.9
A39: Aoci | B39: Sep-26 | C39: =Historicals!$G$170 -> 1664 | D39: reported | E39: Q3-26 release p.11
A40: Apic | B40: Dec-25 | C40: =Historicals!$D$168 -> 37706 | D40: reported | E40: Q2-26 release p.9; Q3-26 release p.11; S-1 p.230
A41: Apic | B41: Jun-26 | C41: =Historicals!$F$168 -> 167344 | D41: reported | E41: Q2-26 release p.9
A42: Apic | B42: Sep-26 | C42: =Historicals!$G$168 -> 212539 | D42: reported | E42: Q3-26 release p.11
A43: Cash | B43: Dec-24 | C43: =Historicals!$C$143 -> 11385 | D43: reported | E43: S-1 p.230
A44: Cash | B44: Dec-25 | C44: =Historicals!$D$143 -> 24747 | D44: reported | E44: Q2-26 release p.9; Q3-26 release p.11; S-1 p.37
A45: Cash | B45: Jun-26 | C45: =Historicals!$F$143 -> 93522 | D45: reported | E45: Q2-26 release p.9
...

Sheet Checks
A1: Checks - every row must be TRUE
A3: Check | B3: Result | C3: Detail
A4: Q1-25: segment revenue sums to total and to income statement | B4: =AND(ABS(Historicals!$C$42+Historicals!$C$54+Historicals!$C$65-Historicals!$C$77)<=1.01,ABS(Historicals!$C$77-Historicals!$C$5)<=1.01) -> TRUE
A5: Q1-25: segment operating income sums to income statement | B5: =ABS(Historicals!$C$47+Historicals!$C$58+Historicals!$C$70-Historicals!$C$12)<=1.01 -> TRUE
A6: Q1-25: Segment Adj. EBITDA sums to consolidated Adj. EBITDA | B6: =ABS(Historicals!$C$50+Historicals!$C$61+Historicals!$C$75-Historicals!$C$37)<=1.01 -> TRUE
A7: Q1-25: segment capex sums to total and to cash-flow capex | B7: =AND(ABS(Historicals!$C$51+Historicals!$C$62+Historicals!$C$76-Historicals!$C$80)<=1.01,ABS(Historicals!$C$80+Historicals!$C$113)<=1.01) -> TRUE
A8: Q1-25: income statement adds up (revenue - costs = EBIT; EBIT to net income) | B8: =AND(ABS(Historicals!$C$5-Historicals!$C$11-Historicals!$C$12)<=1.01,ABS(Historicals!$C$12+Historicals!$C$13+Historicals!$C$14+Historicals!$C$15-Historicals!$C$16)<=1.01,ABS(Historicals!$C$16-Historicals!$C$17-Historicals!$C$18)<=1.01) -> TRUE
A9: Q1-25: Adj. EBITDA reconciles to net income | B9: =AND(ABS(Historicals!$C$26+Historicals!$C$27+Historicals!$C$28+Historicals!$C$29+Historicals!$C$30+Historicals!$C$31+Historicals!$C$32+Historicals!$C$33+Historicals!$C$34+Historicals!$C$35+Historicals!$C$36-Historicals!$C$37)<=1.01,Historicals!$C$26=Historicals!$C$18) -> TRUE
A10: Q2-25: segment revenue sums to total and to income statement | B10: =AND(ABS(Historicals!$D$42+Historicals!$D$54+Historicals!$D$65-Historicals!$D$77)<=1.01,ABS(Historicals!$D$77-Historicals!$D$5)<=1.01) -> TRUE
A11: Q2-25: segment operating income sums to income statement | B11: =ABS(Historicals!$D$47+Historicals!$D$58+Historicals!$D$70-Historicals!$D$12)<=1.01 -> TRUE
A12: Q2-25: Segment Adj. EBITDA sums to consolidated Adj. EBITDA | B12: =ABS(Historicals!$D$50+Historicals!$D$61+Historicals!$D$75-Historicals!$D$37)<=1.01 -> TRUE
A13: Q2-25: segment capex sums to total and to cash-flow capex | B13: =AND(ABS(Historicals!$D$51+Historicals!$D$62+Historicals!$D$76-Historicals!$D$80)<=1.01,ABS(Historicals!$D$80+Historicals!$D$113)<=1.01) -> TRUE
A14: Q2-25: income statement adds up (revenue - costs = EBIT; EBIT to net income) | B14: =AND(ABS(Historicals!$D$5-Historicals!$D$11-Historicals!$D$12)<=1.01,ABS(Historicals!$D$12+Historicals!$D$13+Historicals!$D$14+Historicals!$D$15-Historicals!$D$16)<=1.01,ABS(Historicals!$D$16-Historicals!$D$17-Historicals!$D$18)<=1.01) -> TRUE
A15: Q2-25: Adj. EBITDA reconciles to net income | B15: =AND(ABS(Historicals!$D$26+Historicals!$D$27+Historicals!$D$28+Historicals!$D$29+Historicals!$D$30+Historicals!$D$31+Historicals!$D$32+Historicals!$D$33+Historicals!$D$34+Historicals!$D$35+Historicals!$D$36-Historicals!$D$37)<=1.01,Historicals!$D$26=Historicals!$D$18) -> TRUE
A16: Q3-25: segment revenue sums to total and to income statement | B16: =AND(ABS(Historicals!$E$42+Historicals!$E$54+Historicals!$E$65-Historicals!$E$77)<=1.01,ABS(Historicals!$E$77-Historicals!$E$5)<=1.01) -> TRUE
A17: Q3-25: segment operating income sums to income statement | B17: =ABS(Historicals!$E$47+Historicals!$E$58+Historicals!$E$70-Historicals!$E$12)<=1.01 -> TRUE
A18: Q3-25: Segment Adj. EBITDA sums to consolidated Adj. EBITDA | B18: =ABS(Historicals!$E$50+Historicals!$E$61+Historicals!$E$75-Historicals!$E$37)<=1.01 -> TRUE
A19: Q3-25: segment capex sums to total and to cash-flow capex | B19: =AND(ABS(Historicals!$E$51+Historicals!$E$62+Historicals!$E$76-Historicals!$E$80)<=1.01,ABS(Historicals!$E$80+Historicals!$E$113)<=1.01) -> TRUE
A20: Q3-25: income statement adds up (revenue - costs = EBIT; EBIT to net income) | B20: =AND(ABS(Historicals!$E$5-Historicals!$E$11-Historicals!$E$12)<=1.01,ABS(Historicals!$E$12+Historicals!$E$13+Historicals!$E$14+Historicals!$E$15-Historicals!$E$16)<=1.01,ABS(Historicals!$E$16-Historicals!$E$17-Historicals!$E$18)<=1.01) -> TRUE
A21: Q3-25: Adj. EBITDA reconciles to net income | B21: =AND(ABS(Historicals!$E$26+Historicals!$E$27+Historicals!$E$28+Historicals!$E$29+Historicals!$E$30+Historicals!$E$31+Historicals!$E$32+Historicals!$E$33+Historicals!$E$34+Historicals!$E$35+Historicals!$E$36-Historicals!$E$37)<=1.01,Historicals!$E$26=Historicals!$E$18) -> TRUE
A22: Q4-25: segment revenue sums to total and to income statement | B22: =AND(ABS(Historicals!$F$42+Historicals!$F$54+Historicals!$F$65-Historicals!$F$77)<=1.01,ABS(Historicals!$F$77-Historicals!$F$5)<=1.01) -> TRUE
A23: Q4-25: segment operating income sums to income statement | B23: =ABS(Historicals!$F$47+Historicals!$F$58+Historicals!$F$70-Historicals!$F$12)<=1.01 -> TRUE
A24: Q4-25: Segment Adj. EBITDA sums to consolidated Adj. EBITDA | B24: =ABS(Historicals!$F$50+Historicals!$F$61+Historicals!$F$75-Historicals!$F$37)<=1.01 -> TRUE
A25: Q4-25: segment capex sums to total and to cash-flow capex | B25: =AND(ABS(Historicals!$F$51+Historicals!$F$62+Historicals!$F$76-Historicals!$F$80)<=1.01,ABS(Historicals!$F$80+Historicals!$F$113)<=1.01) -> TRUE
A26: Q4-25: income statement adds up (revenue - costs = EBIT; EBIT to net income) | B26: =AND(ABS(Historicals!$F$5-Historicals!$F$11-Historicals!$F$12)<=1.01,ABS(Historicals!$F$12+Historicals!$F$13+Historicals!$F$14+Historicals!$F$15-Historicals!$F$16)<=1.01,ABS(Historicals!$F$16-Historicals!$F$17-Historicals!$F$18)<=1.01) -> TRUE
A27: Q4-25: Adj. EBITDA reconciles to net income | B27: =AND(ABS(Historicals!$F$26+Historicals!$F$27+Historicals!$F$28+Historicals!$F$29+Historicals!$F$30+Historicals!$F$31+Historicals!$F$32+Historicals!$F$33+Historicals!$F$34+Historicals!$F$35+Historicals!$F$36-Historicals!$F$37)<=1.01,Historicals!$F$26=Historicals!$F$18) -> TRUE
A28: FY25: segment revenue sums to total and to income statement | B28: =AND(ABS(Historicals!$G$42+Historicals!$G$54+Historicals!$G$65-Historicals!$G$77)<=1.01,ABS(Historicals!$G$77-Historicals!$G$5)<=1.01) -> TRUE
A29: FY25: segment operating income sums to income statement | B29: =ABS(Historicals!$G$47+Historicals!$G$58+Historicals!$G$70-Historicals!$G$12)<=1.01 -> TRUE
A30: FY25: Segment Adj. EBITDA sums to consolidated Adj. EBITDA | B30: =ABS(Historicals!$G$50+Historicals!$G$61+Historicals!$G$75-Historicals!$G$37)<=1.01 -> TRUE
A31: FY25: segment capex sums to total and to cash-flow capex | B31: =AND(ABS(Historicals!$G$51+Historicals!$G$62+Historicals!$G$76-Historicals!$G$80)<=1.01,ABS(Historicals!$G$80+Historicals!$G$113)<=1.01) -> TRUE
A32: FY25: income statement adds up (revenue - costs = EBIT; EBIT to net income) | B32: =AND(ABS(Historicals!$G$5-Historicals!$G$11-Historicals!$G$12)<=1.01,ABS(Historicals!$G$12+Historicals!$G$13+Historicals!$G$14+Historicals!$G$15-Historicals!$G$16)<=1.01,ABS(Historicals!$G$16-Historicals!$G$17-Historicals!$G$18)<=1.01) -> TRUE
A33: FY25: Adj. EBITDA reconciles to net income | B33: =AND(ABS(Historicals!$G$26+Historicals!$G$27+Historicals!$G$28+Historicals!$G$29+Historicals!$G$30+Historicals!$G$31+Historicals!$G$32+Historicals!$G$33+Historicals!$G$34+Historicals!$G$35+Historicals!$G$36-Historicals!$G$37)<=1.01,Historicals!$G$26=Historicals!$G$18) -> TRUE
A34: Q1-26: segment revenue sums to total and to income statement | B34: =AND(ABS(Historicals!$H$42+Historicals!$H$54+Historicals!$H$65-Historicals!$H$77)<=1.01,ABS(Historicals!$H$77-Historicals!$H$5)<=1.01) -> TRUE
A35: Q1-26: segment operating income sums to income statement | B35: =ABS(Historicals!$H$47+Historicals!$H$58+Historicals!$H$70-Historicals!$H$12)<=1.01 -> TRUE
A36: Q1-26: Segment Adj. EBITDA sums to consolidated Adj. EBITDA | B36: =ABS(Historicals!$H$50+Historicals!$H$61+Historicals!$H$75-Historicals!$H$37)<=1.01 -> TRUE
A37: Q1-26: segment capex sums to total and to cash-flow capex | B37: =AND(ABS(Historicals!$H$51+Historicals!$H$62+Historicals!$H$76-Historicals!$H$80)<=1.01,ABS(Historicals!$H$80+Historicals!$H$113)<=1.01) -> TRUE
A38: Q1-26: income statement adds up (revenue - costs = EBIT; EBIT to net income) | B38: =AND(ABS(Historicals!$H$5-Historicals!$H$11-Historicals!$H$12)<=1.01,ABS(Historicals!$H$12+Historicals!$H$13+Historicals!$H$14+Historicals!$H$15-Historicals!$H$16)<=1.01,ABS(Historicals!$H$16-Historicals!$H$17-Historicals!$H$18)<=1.01) -> TRUE
A39: Q1-26: Adj. EBITDA reconciles to net income | B39: =AND(ABS(Historicals!$H$26+Historicals!$H$27+Historicals!$H$28+Historicals!$H$29+Historicals!$H$30+Historicals!$H$31+Historicals!$H$32+Historicals!$H$33+Historicals!$H$34+Historicals!$H$35+Historicals!$H$36-Historicals!$H$37)<=1.01,Historicals!$H$26=Historicals!$H$18) -> TRUE
A40: Q2-26: segment revenue sums to total and to income statement | B40: =AND(ABS(Historicals!$I$42+Historicals!$I$54+Historicals!$I$65-Historicals!$I$77)<=1.01,ABS(Historicals!$I$77-Historicals!$I$5)<=1.01) -> TRUE
A41: Q2-26: segment operating income sums to income statement | B41: =ABS(Historicals!$I$47+Historicals!$I$58+Historicals!$I$70-Historicals!$I$12)<=1.01 -> TRUE
...
